INFO:     10.16.2.42:11556 - "POST /auth/login HTTP/1.1" 500 Internal Server Error
ERROR:    Exception in ASGI application
Traceback (most recent call last):
  File "/usr/local/lib/python3.11/site-packages/uvicorn/protocols/http/h11_impl.py", line 403, in run_asgi
    result = await app(  # type: ignore[func-returns-value]
             ^^^^^^^^^^^^^^^^^^^^^^^^^^^^^^^^^^^^^^^^^^^^^^
  File "/usr/local/lib/python3.11/site-packages/uvicorn/middleware/proxy_headers.py", line 60, in __call__
    return await self.app(scope, receive, send)
           ^^^^^^^^^^^^^^^^^^^^^^^^^^^^^^^^^^^^
  File "/usr/local/lib/python3.11/site-packages/fastapi/applications.py", line 1133, in __call__
    await super().__call__(scope, receive, send)
  File "/usr/local/lib/python3.11/site-packages/starlette/applications.py", line 113, in __call__
    await self.middleware_stack(scope, receive, send)
  File "/usr/local/lib/python3.11/site-packages/starlette/middleware/errors.py", line 186, in __call__
    raise exc
  File "/usr/local/lib/python3.11/site-packages/starlette/middleware/errors.py", line 164, in __call__
    await self.app(scope, receive, _send)
  File "/usr/local/lib/python3.11/site-packages/starlette/middleware/cors.py", line 93, in __call__
    await self.simple_response(scope, receive, send, request_headers=headers)
  File "/usr/local/lib/python3.11/site-packages/starlette/middleware/cors.py", line 144, in simple_response
    await self.app(scope, receive, send)
  File "/usr/local/lib/python3.11/site-packages/starlette/middleware/exceptions.py", line 63, in __call__
    await wrap_app_handling_exceptions(self.app, conn)(scope, receive, send)
  File "/usr/local/lib/python3.11/site-packages/starlette/_exception_handler.py", line 53, in wrapped_app
    raise exc
  File "/usr/local/lib/python3.11/site-packages/starlette/_exception_handler.py", line 42, in wrapped_app
    await app(scope, receive, sender)
  File "/usr/local/lib/python3.11/site-packages/fastapi/middleware/asyncexitstack.py", line 18, in __call__
    await self.app(scope, receive, send)
  File "/usr/local/lib/python3.11/site-packages/starlette/routing.py", line 716, in __call__
    await self.middleware_stack(scope, receive, send)
  File "/usr/local/lib/python3.11/site-packages/starlette/routing.py", line 736, in app
    await route.handle(scope, receive, send)
  File "/usr/local/lib/python3.11/site-packages/starlette/routing.py", line 290, in handle
    await self.app(scope, receive, send)
  File "/usr/local/lib/python3.11/site-packages/fastapi/routing.py", line 123, in app
    await wrap_app_handling_exceptions(app, request)(scope, receive, send)
  File "/usr/local/lib/python3.11/site-packages/starlette/_exception_handler.py", line 53, in wrapped_app
    raise exc
  File "/usr/local/lib/python3.11/site-packages/starlette/_exception_handler.py", line 42, in wrapped_app
    await app(scope, receive, sender)
  File "/usr/local/lib/python3.11/site-packages/fastapi/routing.py", line 109, in app
    response = await f(request)
               ^^^^^^^^^^^^^^^^
  File "/usr/local/lib/python3.11/site-packages/fastapi/routing.py", line 389, in app
    raw_response = await run_endpoint_function(
                   ^^^^^^^^^^^^^^^^^^^^^^^^^^^^
  File "/usr/local/lib/python3.11/site-packages/fastapi/routing.py", line 288, in run_endpoint_function
    return await dependant.call(**values)
           ^^^^^^^^^^^^^^^^^^^^^^^^^^^^^^
  File "/app/routes/auth_route.py", line 47, in login
    user = await auth_service.authenticate_user(login_data.username, login_data.password)
           ^^^^^^^^^^^^^^^^^^^^^^^^^^^^^^^^^^^^^^^^^^^^^^^^^^^^^^^^^^^^^^^^^^^^^^^^^^^^^^
  File "/app/services/auth_service.py", line 45, in authenticate_user
    user = await self.users_collection.find_one({"username": username})
           ^^^^^^^^^^^^^^^^^^^^^^^^^^^^^^^^^^^^^^^^^^^^^^^^^^^^^^^^^^^^
  File "/usr/local/lib/python3.11/concurrent/futures/thread.py", line 58, in run
    result = self.fn(*self.args, **self.kwargs)
             ^^^^^^^^^^^^^^^^^^^^^^^^^^^^^^^^^^
  File "/usr/local/lib/python3.11/site-packages/pymongo/synchronous/collection.py", line 1755, in find_one
    for result in cursor.limit(-1):
  File "/usr/local/lib/python3.11/site-packages/pymongo/synchronous/cursor.py", line 1289, in __next__
    return self.next()
           ^^^^^^^^^^^
  File "/usr/local/lib/python3.11/site-packages/pymongo/synchronous/cursor.py", line 1265, in next
    if len(self._data) or self._refresh():
                          ^^^^^^^^^^^^^^^
  File "/usr/local/lib/python3.11/site-packages/pymongo/synchronous/cursor.py", line 1213, in _refresh
    self._send_message(q)
  File "/usr/local/lib/python3.11/site-packages/pymongo/synchronous/cursor.py", line 1108, in _send_message
    response = client._run_operation(
               ^^^^^^^^^^^^^^^^^^^^^^
  File "/usr/local/lib/python3.11/site-packages/pymongo/_csot.py", line 125, in csot_wrapper
    return func(self, *args, **kwargs)
           ^^^^^^^^^^^^^^^^^^^^^^^^^^^
  File "/usr/local/lib/python3.11/site-packages/pymongo/synchronous/mongo_client.py", line 1938, in _run_operation
    return self._retryable_read(
           ^^^^^^^^^^^^^^^^^^^^^
  File "/usr/local/lib/python3.11/site-packages/pymongo/synchronous/mongo_client.py", line 2047, in _retryable_read
    return self._retry_internal(
           ^^^^^^^^^^^^^^^^^^^^^
  File "/usr/local/lib/python3.11/site-packages/pymongo/_csot.py", line 125, in csot_wrapper
    return func(self, *args, **kwargs)
           ^^^^^^^^^^^^^^^^^^^^^^^^^^^
  File "/usr/local/lib/python3.11/site-packages/pymongo/synchronous/mongo_client.py", line 2014, in _retry_internal
    ).run()
      ^^^^^
  File "/usr/local/lib/python3.11/site-packages/pymongo/synchronous/mongo_client.py", line 2765, in run
    return self._read() if self._is_read else self._write()
           ^^^^^^^^^^^^
  File "/usr/local/lib/python3.11/site-packages/pymongo/synchronous/mongo_client.py", line 2910, in _read
    self._server = self._get_server()
                   ^^^^^^^^^^^^^^^^^^
  File "/usr/local/lib/python3.11/site-packages/pymongo/synchronous/mongo_client.py", line 2858, in _get_server
    return self._client._select_server(
           ^^^^^^^^^^^^^^^^^^^^^^^^^^^^
  File "/usr/local/lib/python3.11/site-packages/pymongo/synchronous/mongo_client.py", line 1833, in _select_server
    server = topology.select_server(
             ^^^^^^^^^^^^^^^^^^^^^^^
  File "/usr/local/lib/python3.11/site-packages/pymongo/synchronous/topology.py", line 409, in select_server
    server = self._select_server(
             ^^^^^^^^^^^^^^^^^^^^
  File "/usr/local/lib/python3.11/site-packages/pymongo/synchronous/topology.py", line 387, in _select_server
    servers = self.select_servers(
              ^^^^^^^^^^^^^^^^^^^^
  File "/usr/local/lib/python3.11/site-packages/pymongo/synchronous/topology.py", line 294, in select_servers
    server_descriptions = self._select_servers_loop(
                          ^^^^^^^^^^^^^^^^^^^^^^^^^^
  File "/usr/local/lib/python3.11/site-packages/pymongo/synchronous/topology.py", line 344, in _select_servers_loop
    raise ServerSelectionTimeoutError(
pymongo.errors.ServerSelectionTimeoutError: SSL handshake failed: ac-ogykxrs-shard-00-00.l6dgzkj.mongodb.net:27017: [SSL: TLSV1_ALERT_INTERNAL_ERROR] tlsv1 alert internal error (_ssl.c:1016) (configured timeouts: socketTimeoutMS: 20000.0ms, connectTimeoutMS: 20000.0ms),SSL handshake failed: ac-ogykxrs-shard-00-02.l6dgzkj.mongodb.net:27017: [SSL: TLSV1_ALERT_INTERNAL_ERROR] tlsv1 alert internal error (_ssl.c:1016) (configured timeouts: socketTimeoutMS: 20000.0ms, connectTimeoutMS: 20000.0ms),SSL handshake failed: ac-ogykxrs-shard-00-01.l6dgzkj.mongodb.net:27017: [SSL: TLSV1_ALERT_INTERNAL_ERROR] tlsv1 alert internal error (_ssl.c:1016) (configured timeouts: socketTimeoutMS: 20000.0ms, connectTimeoutMS: 20000.0ms), Timeout: 30s, Topology Description: <TopologyDescription id: 68f747837286b5292229b5bc, topology_type: ReplicaSetNoPrimary, servers: [<ServerDescription ('ac-ogykxrs-shard-00-00.l6dgzkj.mongodb.net', 27017) server_type: Unknown, rtt: None, error=AutoReconnect('SSL handshake failed: ac-ogykxrs-shard-00-00.l6dgzkj.mongodb.net:27017: [SSL: TLSV1_ALERT_INTERNAL_ERROR] tlsv1 alert internal error (_ssl.c:1016) (configured timeouts: socketTimeoutMS: 20000.0ms, connectTimeoutMS: 20000.0ms)')>, <ServerDescription ('ac-ogykxrs-shard-00-01.l6dgzkj.mongodb.net', 27017) server_type: Unknown, rtt: None, error=AutoReconnect('SSL handshake failed: ac-ogykxrs-shard-00-01.l6dgzkj.mongodb.net:27017: [SSL: TLSV1_ALERT_INTERNAL_ERROR] tlsv1 alert internal error (_ssl.c:1016) (configured timeouts: socketTimeoutMS: 20000.0ms, connectTimeoutMS: 20000.0ms)')>, <ServerDescription ('ac-ogykxrs-shard-00-02.l6dgzkj.mongodb.net', 27017) server_type: Unknown, rtt: None, error=AutoReconnect('SSL handshake failed: ac-ogykxrs-shard-00-02.l6dgzkj.mongodb.net:27017: [SSL: TLSV1_ALERT_INTERNAL_ERROR] tlsv1 alert internal error (_ssl.c:1016) (configured timeouts: socketTimeoutMS: 20000.0ms, connectTimeoutMS: 20000.0ms)')>]>